<?xml version="1.0" encoding="UTF-8"?>
<!-- Generated by org.testng.reporters.JUnitXMLReporter -->
<testsuite hostname="WINDOWS-JQDUD0F" name="Default test" tests="5" failures="1" timestamp="2 Feb 2018 06:54:01 GMT" time="4.419" errors="0">
  <testcase name="Login" time="0.991" classname="interface_login.login_test">
    <failure type="java.lang.AssertionError" message="expected [true] but found [\NET\Team2\稽查\V3.0\Log\2018-02-02”的访问被拒绝。&amp;lt;/title&amp;gt;
        &amp;lt;meta name=&amp;quot;viewport&amp;quot; content=&amp;quot;width=device-width&amp;quot; /&amp;gt;
        &amp;lt;style&amp;gt;
         body {font-family]">
      <![CDATA[java.lang.AssertionError: expected [true] but found [\NET\Team2\稽查\V3.0\Log\2018-02-02”的访问被拒绝。</title>
        <meta name="viewport" content="width=device-width" />
        <style>
         body {font-family]
	at org.testng.Assert.fail(Assert.java:94)
	at org.testng.Assert.failNotEquals(Assert.java:496)
	at org.testng.Assert.assertEquals(Assert.java:125)
	at org.testng.Assert.assertEquals(Assert.java:178)
	at org.testng.Assert.assertEquals(Assert.java:188)
	at interface_login.login_test.Login(login_test.java:60)
	at sun.reflect.NativeMethodAccessorImpl.invoke0(Native Method)
	at sun.reflect.NativeMethodAccessorImpl.invoke(NativeMethodAccessorImpl.java:62)
	at sun.reflect.DelegatingMethodAccessorImpl.invoke(DelegatingMethodAccessorImpl.java:43)
	at java.lang.reflect.Method.invoke(Method.java:498)
	at org.testng.internal.MethodInvocationHelper.invokeMethod(MethodInvocationHelper.java:85)
	at org.testng.internal.Invoker.invokeMethod(Invoker.java:639)
	at org.testng.internal.Invoker.invokeTestMethod(Invoker.java:816)
	at org.testng.internal.Invoker.invokeTestMethods(Invoker.java:1124)
	at org.testng.internal.TestMethodWorker.invokeTestMethods(TestMethodWorker.java:125)
	at org.testng.internal.TestMethodWorker.run(TestMethodWorker.java:108)
	at org.testng.TestRunner.privateRun(TestRunner.java:774)
	at org.testng.TestRunner.run(TestRunner.java:624)
	at org.testng.SuiteRunner.runTest(SuiteRunner.java:359)
	at org.testng.SuiteRunner.runSequentially(SuiteRunner.java:354)
	at org.testng.SuiteRunner.privateRun(SuiteRunner.java:312)
	at org.testng.SuiteRunner.run(SuiteRunner.java:261)
	at org.testng.SuiteRunnerWorker.runSuite(SuiteRunnerWorker.java:52)
	at org.testng.SuiteRunnerWorker.run(SuiteRunnerWorker.java:86)
	at org.testng.TestNG.runSuitesSequentially(TestNG.java:1191)
	at org.testng.TestNG.runSuitesLocally(TestNG.java:1116)
	at org.testng.TestNG.run(TestNG.java:1024)
	at org.testng.remote.RemoteTestNG.run(RemoteTestNG.java:112)
	at org.testng.remote.RemoteTestNG.initAndRun(RemoteTestNG.java:205)
	at org.testng.remote.RemoteTestNG.main(RemoteTestNG.java:176)
]]>
    </failure>
  </testcase> <!-- Login -->
  <testcase name="Login" time="2.683" classname="interface_login.login_test"/>
  <testcase name="Login" time="0.035" classname="interface_login.login_test"/>
  <testcase name="Login" time="0.069" classname="interface_login.login_test"/>
  <testcase name="Login" time="0.164" classname="interface_login.login_test"/>
</testsuite> <!-- Default test -->
